Workbook

Sheet Main_Data
A1: Sector | B1: Year | C1: Month | D1: Cereals and products | E1: Meat and fish | F1: Egg | G1: Milk and products | H1: Oils and fats | I1: Fruits | J1: Vegetables | K1: Pulses and products | L1: Sugar and Confectionery | M1: Spices | N1: Non-alcoholic beverages | O1: Prepared meals, snacks, sweets etc. | P1: Food and beverages | Q1: Pan, tobacco and intoxicants | R1: Clothing | S1: Footwear | T1: Clothing and footwear | U1: Housing | V1: Fuel and light | W1: Household goods and services | X1: Health | Y1: Transport and communication | Z1: Recreation and amusement | AA1: Education | AB1: Personal care and effects | AC1: Miscellaneous | AD1: General index
A2: Rural | B2: 2013 | C2: January | D2: 107.5 | E2: 106.3 | F2: 108.1 | G2: 104.9 | H2: 106.1 | I2: 103.9 | J2: 101.9 | K2: 106.1 | L2: 106.8 | M2: 103.1 | N2: 104.8 | O2: 106.7 | P2: 105.5 | Q2: 105.1 | R2: 106.5 | S2: 105.8 | T2: 106.4 | U2: NA | V2: 105.5 | W2: 104.8 | X2: 104 | Y2: 103.3 | Z2: 103.4 | AA2: 103.8 | AB2: 104.7 | AC2: 104 | AD2: 105.1
A3: Urban | B3: 2013 | C3: January | D3: 110.5 | E3: 109.1 | F3: 113 | G3: 103.6 | H3: 103.4 | I3: 102.3 | J3: 102.9 | K3: 105.8 | L3: 105.1 | M3: 101.8 | N3: 105.1 | O3: 107.9 | P3: 105.9 | Q3: 105.2 | R3: 105.9 | S3: 105 | T3: 105.8 | U3: 100.3 | V3: 105.4 | W3: 104.8 | X3: 104.1 | Y3: 103.2 | Z3: 102.9 | AA3: 103.5 | AB3: 104.3 | AC3: 103.7 | AD3: 104
A4: Rural+Urban | B4: 2013 | C4: January | D4: 108.4 | E4: 107.3 | F4: 110 | G4: 104.4 | H4: 105.1 | I4: 103.2 | J4: 102.2 | K4: 106 | L4: 106.2 | M4: 102.7 | N4: 104.9 | O4: 107.3 | P4: 105.6 | Q4: 105.1 | R4: 106.3 | S4: 105.5 | T4: 106.2 | U4: 100.3 | V4: 105.5 | W4: 104.8 | X4: 104 | Y4: 103.2 | Z4: 103.1 | AA4: 103.6 | AB4: 104.5 | AC4: 103.9 | AD4: 104.6
A5: Rural | B5: 2013 | C5: February | D5: 109.2 | E5: 108.7 | F5: 110.2 | G5: 105.4 | H5: 106.7 | I5: 104 | J5: 102.4 | K5: 105.9 | L5: 105.7 | M5: 103.1 | N5: 105.1 | O5: 107.7 | P5: 106.3 | Q5: 105.6 | R5: 107.1 | S5: 106.3 | T5: 107 | U5: NA | V5: 106.2 | W5: 105.2 | X5: 104.4 | Y5: 103.9 | Z5: 104 | AA5: 104.1 | AB5: 104.6 | AC5: 104.4 | AD5: 105.8
A6: Urban | B6: 2013 | C6: February | D6: 112.9 | E6: 112.9 | F6: 116.9 | G6: 104 | H6: 103.5 | I6: 103.1 | J6: 104.9 | K6: 104.1 | L6: 103.8 | M6: 102.3 | N6: 106 | O6: 109 | P6: 107.2 | Q6: 106 | R6: 106.6 | S6: 105.5 | T6: 106.4 | U6: 100.4 | V6: 105.7 | W6: 105.2 | X6: 104.7 | Y6: 104.4 | Z6: 103.3 | AA6: 103.7 | AB6: 104.3 | AC6: 104.3 | AD6: 104.7
A7: Rural+Urban | B7: 2013 | C7: February | D7: 110.4 | E7: 110.2 | F7: 112.8 | G7: 104.9 | H7: 105.5 | I7: 103.6 | J7: 103.2 | K7: 105.3 | L7: 105.1 | M7: 102.8 | N7: 105.5 | O7: 108.3 | P7: 106.6 | Q7: 105.7 | R7: 106.9 | S7: 106 | T7: 106.8 | U7: 100.4 | V7: 106 | W7: 105.2 | X7: 104.5 | Y7: 104.2 | Z7: 103.6 | AA7: 103.9 | AB7: 104.5 | AC7: 104.4 | AD7: 105.3
A8: Rural | B8: 2013 | C8: March | D8: 110.2 | E8: 108.8 | F8: 109.9 | G8: 105.6 | H8: 106.2 | I8: 105.7 | J8: 101.4 | K8: 105.7 | L8: 105 | M8: 103.3 | N8: 105.6 | O8: 108.2 | P8: 106.6 | Q8: 106.5 | R8: 107.6 | S8: 106.8 | T8: 107.5 | U8: NA | V8: 106.1 | W8: 105.6 | X8: 104.7 | Y8: 104.6 | Z8: 104 | AA8: 104.3 | AB8: 104.3 | AC8: 104.6 | AD8: 106
A9: Urban | B9: 2013 | C9: March | D9: 113.9 | E9: 111.4 | F9: 113.2 | G9: 104.3 | H9: 102.7 | I9: 104.9 | J9: 103.8 | K9: 103.5 | L9: 102.6 | M9: 102.4 | N9: 107 | O9: 109.8 | P9: 107.3 | Q9: 106.8 | R9: 107.2 | S9: 106 | T9: 107 | U9: 100.4 | V9: 106 | W9: 105.7 | X9: 105.2 | Y9: 105.5 | Z9: 103.5 | AA9: 103.8 | AB9: 104.2 | AC9: 104.9 | AD9: 105
A10: Rural+Urban | B10: 2013 | C10: March | D10: 111.4 | E10: 109.7 | F10: 111.2 | G10: 105.1 | H10: 104.9 | I10: 105.3 | J10: 102.2 | K10: 105 | L10: 104.2 | M10: 103 | N10: 106.2 | O10: 108.9 | P10: 106.9 | Q10: 106.6 | R10: 107.4 | S10: 106.5 | T10: 107.3 | U10: 100.4 | V10: 106.1 | W10: 105.6 | X10: 104.9 | Y10: 105.1 | Z10: 103.7 | AA10: 104 | AB10: 104.3 | AC10: 104.7 | AD10: 105.5
A11: Rural | B11: 2013 | C11: April | D11: 110.2 | E11: 109.5 | F11: 106.9 | G11: 106.3 | H11: 105.7 | I11: 108.3 | J11: 103.4 | K11: 105.7 | L11: 104.2 | M11: 103.2 | N11: 106.5 | O11: 108.8 | P11: 107.1 | Q11: 107.1 | R11: 108.1 | S11: 107.4 | T11: 108 | U11: NA | V11: 106.5 | W11: 106.1 | X11: 105.1 | Y11: 104.4 | Z11: 104.5 | AA11: 104.8 | AB11: 102.7 | AC11: 104.6 | AD11: 106.4
A12: Urban | B12: 2013 | C12: April | D12: 114.6 | E12: 113.4 | F12: 106 | G12: 104.7 | H12: 102.1 | I12: 109.5 | J12: 109.7 | K12: 104.6 | L12: 102 | M12: 103.5 | N12: 108.2 | O12: 110.6 | P12: 108.8 | Q12: 108.5 | R12: 107.9 | S12: 106.4 | T12: 107.7 | U12: 100.5 | V12: 106.4 | W12: 106.5 | X12: 105.7 | Y12: 105 | Z12: 104 | AA12: 105.2 | AB12: 103.2 | AC12: 105.1 | AD12: 105.7
A13: Rural+Urban | B13: 2013 | C13: April | D13: 111.6 | E13: 110.9 | F13: 106.6 | G13: 105.7 | H13: 104.4 | I13: 108.9 | J13: 105.5 | K13: 105.3 | L13: 103.5 | M13: 103.3 | N13: 107.2 | O13: 109.6 | P13: 107.7 | Q13: 107.5 | R13: 108 | S13: 107 | T13: 107.9 | U13: 100.5 | V13: 106.5 | W13: 106.3 | X13: 105.3 | Y13: 104.7 | Z13: 104.2 | AA13: 105 | AB13: 102.9 | AC13: 104.8 | AD13: 106.1
A14: Rural | B14: 2013 | C14: May | D14: 110.9 | E14: 109.8 | F14: 105.9 | G14: 107.5 | H14: 105.3 | I14: 108.1 | J14: 107.3 | K14: 106.1 | L14: 103.7 | M14: 104 | N14: 107.4 | O14: 109.9 | P14: 108.1 | Q14: 108.1 | R14: 108.8 | S14: 107.9 | T14: 108.6 | U14: NA | V14: 107.5 | W14: 106.8 | X14: 105.7 | Y14: 104.1 | Z14: 105 | AA14: 105.5 | AB14: 102.1 | AC14: 104.8 | AD14: 107.2
A15: Urban | B15: 2013 | C15: May | D15: 115.4 | E15: 114.2 | F15: 102.7 | G15: 105.5 | H15: 101.5 | I15: 110.6 | J15: 123.7 | K15: 105.2 | L15: 101.9 | M15: 105 | N15: 109.1 | O15: 111.3 | P15: 111.1 | Q15: 109.8 | R15: 108.5 | S15: 106.7 | T15: 108.3 | U15: 100.5 | V15: 107.2 | W15: 107.1 | X15: 106.2 | Y15: 103.9 | Z15: 104.6 | AA15: 105.7 | AB15: 102.6 | AC15: 104.9 | AD15: 106.6
A16: Rural+Urban | B16: 2013 | C16: May | D16: 112.3 | E16: 111.3 | F16: 104.7 | G16: 106.8 | H16: 103.9 | I16: 109.3 | J16: 112.9 | K16: 105.8 | L16: 103.1 | M16: 104.3 | N16: 108.1 | O16: 110.5 | P16: 109.2 | Q16: 108.6 | R16: 108.7 | S16: 107.4 | T16: 108.5 | U16: 100.5 | V16: 107.4 | W16: 106.9 | X16: 105.9 | Y16: 104 | Z16: 104.8 | AA16: 105.6 | AB16: 102.3 | AC16: 104.8 | AD16: 106.9
A17: Rural | B17: 2013 | C17: June | D17: 112.3 | E17: 112.1 | F17: 108.1 | G17: 108.3 | H17: 105.9 | I17: 109.2 | J17: 118 | K17: 106.8 | L17: 104.1 | M17: 105.4 | N17: 108.2 | O17: 111 | P17: 110.6 | Q17: 109 | R17: 109.7 | S17: 108.8 | T17: 109.5 | U17: NA | V17: 108.5 | W17: 107.5 | X17: 106.3 | Y17: 105 | Z17: 105.6 | AA17: 106.5 | AB17: 102.5 | AC17: 105.5 | AD17: 108.9
A18: Urban | B18: 2013 | C18: June | D18: 117 | E18: 120.1 | F18: 112.5 | G18: 107.3 | H18: 101.3 | I18: 112.4 | J18: 143.6 | K18: 105.4 | L18: 101.4 | M18: 106.4 | N18: 110 | O18: 112.2 | P18: 115 | Q18: 110.9 | R18: 109.2 | S18: 107.2 | T18: 108.9 | U18: 106.6 | V18: 108 | W18: 107.7 | X18: 106.5 | Y18: 105.2 | Z18: 105.2 | AA18: 108.1 | AB18: 103.3 | AC18: 106.1 | AD18: 109.7
A19: Rural+Urban | B19: 2013 | C19: June | D19: 113.8 | E19: 114.9 | F19: 109.8 | G19: 107.9 | H19: 104.2 | I19: 110.7 | J19: 126.7 | K19: 106.3 | L19: 103.2 | M19: 105.7 | N19: 109 | O19: 111.6 | P19: 112.2 | Q19: 109.5 | R19: 109.5 | S19: 108.1 | T19: 109.3 | U19: 106.6 | V19: 108.3 | W19: 107.6 | X19: 106.4 | Y19: 105.1 | Z19: 105.4 | AA19: 107.4 | AB19: 102.8 | AC19: 105.8 | AD19: 109.3
A20: Rural | B20: 2013 | C20: July | D20: 113.4 | E20: 114.9 | F20: 110.5 | G20: 109.3 | H20: 106.2 | I20: 110.3 | J20: 129.2 | K20: 107.1 | L20: 104.3 | M20: 106.4 | N20: 109.1 | O20: 112.1 | P20: 113.1 | Q20: 109.8 | R20: 110.5 | S20: 109.5 | T20: 110.3 | U20: NA | V20: 109.5 | W20: 108.3 | X20: 106.9 | Y20: 106.8 | Z20: 106.4 | AA20: 107.8 | AB20: 102.5 | AC20: 106.5 | AD20: 110.7
A21: Urban | B21: 2013 | C21: July | D21: 117.8 | E21: 119.2 | F21: 114 | G21: 108.3 | H21: 101.1 | I21: 113.2 | J21: 160.9 | K21: 105.1 | L21: 101.3 | M21: 107.5 | N21: 110.4 | O21: 113.1 | P21: 117.5 | Q21: 111.7 | R21: 109.8 | S21: 107.8 | T21: 109.5 | U21: 107.7 | V21: 108.6 | W21: 108.1 | X21: 107.1 | Y21: 107.3 | Z21: 105.9 | AA21: 110.1 | AB21: 103.2 | AC21: 107.3 | AD21: 111.4
A22: Rural+Urban | B22: 2013 | C22: July | D22: 114.8 | E22: 116.4 | F22: 111.9 | G22: 108.9 | H22: 104.3 | I22: 111.7 | J22: 140 | K22: 106.4 | L22: 103.3 | M22: 106.8 | N22: 109.6 | O22: 112.6 | P22: 114.7 | Q22: 110.3 | R22: 110.2 | S22: 108.8 | T22: 110 | U22: 107.7 | V22: 109.2 | W22: 108.2 | X22: 107 | Y22: 107.1 | Z22: 106.1 | AA22: 109.1 | AB22: 102.8 | AC22: 106.9 | AD22: 111
A23: Rural | B23: 2013 | C23: August | D23: 114.3 | E23: 115.4 | F23: 111.1 | G23: 110 | H23: 106.4 | I23: 110.8 | J23: 138.9 | K23: 107.4 | L23: 104.1 | M23: 106.9 | N23: 109.7 | O23: 112.6 | P23: 114.9 | Q23: 110.7 | R23: 111.3 | S23: 110.2 | T23: 111.1 | U23: NA | V23: 109.9 | W23: 108.7 | X23: 107.5 | Y23: 107.8 | Z23: 106.8 | AA23: 108.7 | AB23: 105 | AC23: 107.5 | AD23: 112.1
A24: Urban | B24: 2013 | C24: August | D24: 118.3 | E24: 120.4 | F24: 112.7 | G24: 108.9 | H24: 101.1 | I24: 108.7 | J24: 177 | K24: 104.7 | L24: 101 | M24: 108.5 | N24: 110.9 | O24: 114.3 | P24: 119.6 | Q24: 112.4 | R24: 110.6 | S24: 108.3 | T24: 110.2 | U24: 108.9 | V24: 109.3 | W24: 108.7 | X24: 107.6 | Y24: 108.1 | Z24: 106.5 | AA24: 110.8 | AB24: 106 | AC24: 108.3 | AD24: 112.7
A25: Rural+Urban | B25: 2013 | C25: August | D25: 115.6 | E25: 117.2 | F25: 111.7 | G25: 109.6 | H25: 104.5 | I25: 109.8 | J25: 151.8 | K25: 106.5 | L25: 103.1 | M25: 107.4 | N25: 110.2 | O25: 113.4 | P25: 116.6 | Q25: 111.2 | R25: 111 | S25: 109.4 | T25: 110.7 | U25: 108.9 | V25: 109.7 | W25: 108.7 | X25: 107.5 | Y25: 108 | Z25: 106.6 | AA25: 109.9 | AB25: 105.4 | AC25: 107.9 | AD25: 112.4
A26: Rural | B26: 2013 | C26: September | D26: 115.4 | E26: 115.7 | F26: 111.7 | G26: 111 | H26: 107.4 | I26: 110.9 | J26: 154 | K26: 108.1 | L26: 104.2 | M26: 107.9 | N26: 110.4 | O26: 114 | P26: 117.8 | Q26: 111.7 | R26: 112.7 | S26: 111.4 | T26: 112.5 | U26: NA | V26: 111.1 | W26: 109.6 | X26: 108.3 | Y26: 109.3 | Z26: 107.7 | AA26: 109.8 | AB26: 106.7 | AC26: 108.7 | AD26: 114.2
A27: Urban | B27: 2013 | C27: September | D27: 118.6 | E27: 119.1 | F27: 113.2 | G27: 109.6 | H27: 101.7 | I27: 103.2 | J27: 174.3 | K27: 105.1 | L27: 100.8 | M27: 109.1 | N27: 111.1 | O27: 115.4 | P27: 119.2 | Q27: 112.9 | R27: 111.4 | S27: 109 | T27: 111.1 | U27: 109.7 | V27: 109.5 | W27: 109.6 | X27: 107.9 | Y27: 110.4 | Z27: 107.4 | AA27: 111.2 | AB27: 106.9 | AC27: 109.4 | AD27: 113.2
A28: Rural+Urban | B28: 2013 | C28: September | D28: 116.4 | E28: 116.9 | F28: 112.3 | G28: 110.5 | H28: 105.3 | I28: 107.3 | J28: 160.9 | K28: 107.1 | L28: 103.1 | M28: 108.3 | N28: 110.7 | O28: 114.6 | P28: 118.3 | Q28: 112 | R28: 112.2 | S28: 110.4 | T28: 111.9 | U28: 109.7 | V28: 110.5 | W28: 109.6 | X28: 108.1 | Y28: 109.9 | Z28: 107.5 | AA28: 110.6 | AB28: 106.8 | AC28: 109 | AD28: 113.7
A29: Rural | B29: 2013 | C29: October | D29: 116.3 | E29: 115.4 | F29: 112.6 | G29: 111.7 | H29: 107.7 | I29: 113.2 | J29: 164.9 | K29: 108.3 | L29: 103.9 | M29: 108.2 | N29: 111.1 | O29: 114.9 | P29: 119.8 | Q29: 112.2 | R29: 113.6 | S29: 112.3 | T29: 113.4 | U29: NA | V29: 111.6 | W29: 110.4 | X29: 108.9 | Y29: 109.3 | Z29: 108.3 | AA29: 110.2 | AB29: 107.5 | AC29: 109.1 | AD29: 115.5
A30: Urban | B30: 2013 | C30: October | D30: 118.9 | E30: 118.1 | F30: 114.5 | G30: 110.4 | H30: 102.3 | I30: 106.2 | J30: 183.5 | K30: 105.3 | L30: 100.2 | M30: 109.6 | N30: 111.4 | O30: 116 | P30: 120.8 | Q30: 113.5 | R30: 112.5 | S30: 109.7 | T30: 112 | U30: 110.5 | V30: 109.7 | W30: 110.2 | X30: 108.2 | Y30: 109.7 | Z30: 108 | AA30: 111.3 | AB30: 107.3 | AC30: 109.4 | AD30: 114
A31: Rural+Urban | B31: 2013 | C31: October | D31: 117.1 | E31: 116.3 | F31: 113.3 | G31: 111.2 | H31: 105.7 | I31: 109.9 | J31: 171.2 | K31: 107.3 | L31: 102.7 | M31: 108.7 | N31: 111.2 | O31: 115.4 | P31: 120.2 | Q31: 112.5 | R31: 113.2 | S31: 111.2 | T31: 112.8 | U31: 110.5 | V31: 110.9 | W31: 110.3 | X31: 108.6 | Y31: 109.5 | Z31: 108.1 | AA31: 110.8 | AB31: 107.4 | AC31: 109.2 | AD31: 114.8
A32: Rural | B32: 2013 | C32: November | D32: 117.3 | E32: 114.9 | F32: 116.2 | G32: 112.8 | H32: 108.9 | I32: 116.6 | J32: 178.1 | K32: 109.1 | L32: 103.6 | M32: 109 | N32: 111.8 | O32: 116 | P32: 122.5 | Q32: 112.8 | R32: 114.6 | S32: 113.1 | T32: 114.4 | U32: NA | V32: 112.6 | W32: 111.3 | X32: 109.7 | Y32: 109.6 | Z32: 108.7 | AA32: 111 | AB32: 108.2 | AC32: 109.8 | AD32: 117.4
A33: Urban | B33: 2013 | C33: November | D33: 119.8 | E33: 116.3 | F33: 122.6 | G33: 112 | H33: 103.2 | I33: 110 | J33: 192.8 | K33: 106.3 | L33: 99.5 | M33: 110.3 | N33: 111.8 | O33: 117.1 | P33: 122.9 | Q33: 114.1 | R33: 113.5 | S33: 110.3 | T33: 113 | U33: 111.1 | V33: 110 | W33: 110.9 | X33: 108.6 | Y33: 109.5 | Z33: 108.5 | AA33: 111.3 | AB33: 107.9 | AC33: 109.6 | AD33: 115
A34: Rural+Urban | B34: 2013 | C34: November | D34: 118.1 | E34: 115.4 | F34: 118.7 | G34: 112.5 | H34: 106.8 | I34: 113.5 | J34: 183.1 | K34: 108.2 | L34: 102.2 | M34: 109.4 | N34: 111.8 | O34: 116.5 | P34: 122.6 | Q34: 113.1 | R34: 114.2 | S34: 111.9 | T34: 113.8 | U34: 111.1 | V34: 111.6 | W34: 111.1 | X34: 109.3 | Y34: 109.5 | Z34: 108.6 | AA34: 111.2 | AB34: 108.1 | AC34: 109.7 | AD34: 116.3
A35: Rural | B35: 2013 | C35: December | D35: 118.4 | E35: 115.9 | F35: 120.4 | G35: 113.8 | H35: 109.5 | I35: 115.5 | J35: 145.7 | K35: 109.5 | L35: 102.9 | M35: 109.8 | N35: 112.1 | O35: 116.8 | P35: 118.7 | Q35: 113.6 | R35: 115.8 | S35: 114 | T35: 115.5 | U35: NA | V35: 112.8 | W35: 112.1 | X35: 110.1 | Y35: 109.9 | Z35: 109.2 | AA35: 111.6 | AB35: 108.1 | AC35: 110.1 | AD35: 115.5
A36: Urban | B36: 2013 | C36: December | D36: 120.5 | E36: 118.1 | F36: 128.5 | G36: 112.8 | H36: 103.4 | I36: 110.7 | J36: 144.8 | K36: 107.1 | L36: 98.6 | M36: 111.9 | N36: 112.1 | O36: 118.1 | P36: 117.8 | Q36: 115 | R36: 114.2 | S36: 110.9 | T36: 113.7 | U36: 110.7 | V36: 110.4 | W36: 111.3 | X36: 109 | Y36: 109.7 | Z36: 108.9 | AA36: 111.4 | AB36: 107.7 | AC36: 109.8 | AD36: 113.3
A37: Rural+Urban | B37: 2013 | C37: December | D37: 119.1 | E37: 116.7 | F37: 123.5 | G37: 113.4 | H37: 107.3 | I37: 113.3 | J37: 145.4 | K37: 108.7 | L37: 101.5 | M37: 110.5 | N37: 112.1 | O37: 117.4 | P37: 118.4 | Q37: 114 | R37: 115.2 | S37: 112.7 | T37: 114.8 | U37: 110.7 | V37: 111.9 | W37: 111.7 | X37: 109.7 | Y37: 109.8 | Z37: 109 | AA37: 111.5 | AB37: 107.9 | AC37: 110 | AD37: 114.5
A38: Rural | B38: 2014 | C38: January | D38: 118.9 | E38: 117.1 | F38: 120.5 | G38: 114.4 | H38: 109 | I38: 115.5 | J38: 123.9 | K38: 109.6 | L38: 101.8 | M38: 110.2 | N38: 112.4 | O38: 117.3 | P38: 116 | Q38: 114 | R38: 116.5 | S38: 114.5 | T38: 116.2 | U38: NA | V38: 113 | W38: 112.6 | X38: 110.6 | Y38: 110.5 | Z38: 109.6 | AA38: 111.8 | AB38: 108.3 | AC38: 110.6 | AD38: 114.2
A39: Urban | B39: 2014 | C39: January | D39: 121.2 | E39: 122 | F39: 129.9 | G39: 113.6 | H39: 102.9 | I39: 112.1 | J39: 118.9 | K39: 107.5 | L39: 96.9 | M39: 112.7 | N39: 112.1 | O39: 119 | P39: 115.5 | Q39: 115.7 | R39: 114.8 | S39: 111.3 | T39: 114.3 | U39: 111.6 | V39: 111 | W39: 111.9 | X39: 109.7 | Y39: 110.8 | Z39: 109.8 | AA39: 111.5 | AB39: 108 | AC39: 110.5 | AD39: 112.9
A40: Rural+Urban | B40: 2014 | C40: January | D40: 119.6 | E40: 118.8 | F40: 124.1 | G40: 114.1 | H40: 106.8 | I40: 113.9 | J40: 122.2 | K40: 108.9 | L40: 100.2 | M40: 111 | N40: 112.3 | O40: 118.1 | P40: 115.8 | Q40: 114.5 | R40: 115.8 | S40: 113.2 | T40: 115.4 | U40: 111.6 | V40: 112.2 | W40: 112.3 | X40: 110.3 | Y40: 110.7 | Z40: 109.7 | AA40: 111.6 | AB40: 108.2 | AC40: 110.6 | AD40: 113.6
...

Sheet Sheet3
A1: Sector | B1: Broader Buckets | C1: Rural | D1: Urban | E1: Rural+Urban | F1: Rural | G1: Urban | H1: Rural+Urban | I1: Rural | J1: Urban | K1: Rural+Urban | L1: Rural | M1: Urban | N1: Rural+Urban | O1: Rural | P1: Urban | Q1: Rural+Urban | R1: Rural | S1: Urban | T1: Rural+Urban | U1: Rural | V1: Urban | W1: Rural+Urban | X1: Rural | Y1: Urban | Z1: Rural+Urban | AA1: Rural | AB1: Urban | AC1: Rural+Urban | AD1: Rural | AE1: Urban | AF1: Rural+Urban | AG1: Rural | AH1: Urban | AI1: Rural+Urban | AJ1: Rural | AK1: Urban | AL1: Rural+Urban | AM1: Rural | AN1: Urban | AO1: Rural+Urban | AP1: Rural | AQ1: Urban | AR1: Rural+Urban | AS1: Rural | AT1: Urban | AU1: Rural+Urban | AV1: Rural | AW1: Urban | AX1: Rural+Urban | AY1: Rural | AZ1: Urban | BA1: Rural+Urban | BB1: Rural | BC1: Urban | BD1: Rural+Urban | BE1: Rural | BF1: Urban | BG1: Rural+Urban | BH1: Rural | BI1: Urban | BJ1: Rural+Urban | BK1: Rural | BL1: Urban | BM1: Rural+Urban | BN1: Rural | BO1: Urban | BP1: Rural+Urban | BQ1: Rural | BR1: Urban | BS1: Rural+Urban | BT1: Rural | BU1: Urban | BV1: Rural+Urban | BW1: Rural | BX1: Urban | BY1: Rural+Urban | BZ1: Rural | CA1: Urban | CB1: Rural+Urban | CC1: Rural | CD1: Urban | CE1: Rural+Urban | CF1: Rural | CG1: Urban | CH1: Rural+Urban | CI1: Rural | CJ1: Urban | CK1: Rural+Urban | CL1: Rural | CM1: Urban | CN1: Rural+Urban | CO1: Rural | CP1: Urban | CQ1: Rural+Urban | CR1: Rural | CS1: Urban | CT1: Rural+Urban | CU1: Rural | CV1: Urban | CW1: Rural+Urban | CX1: Rural | CY1: Urban | CZ1: Rural+Urban | DA1: Rural | DB1: Urban | DC1: Rural+Urban | DD1: Rural | DE1: Urban | DF1: Rural+Urban | DG1: Rural | DH1: Urban | DI1: Rural+Urban | DJ1: Rural | DK1: Urban | DL1: Rural+Urban | DM1: Rural | DN1: Urban | DO1: Rural+Urban | DP1: Rural | DQ1: Urban | DR1: Rural+Urban | DS1: Rural | DT1: Urban | DU1: Rural+Urban | DV1: Rural | DW1: Urban | DX1: Rural+Urban | DY1: Rural | DZ1: Urban | EA1: Rural+Urban | EB1: Rural | EC1: Urban | ED1: Rural+Urban | EE1: Rural | EF1: Urban | EG1: Rural+Urban | EH1: Rural | EI1: Urban | EJ1: Rural+Urban | EK1: Rural | EL1: Urban | EM1: Rural+Urban | EN1: Rural | EO1: Urban | EP1: Rural+Urban | EQ1: Rural | ER1: Urban | ES1: Rural+Urban | ET1: Rural | EU1: Urban | EV1: Rural+Urban | EW1: Rural | EX1: Urban | EY1: Rural+Urban | EZ1: Rural | FA1: Urban | FB1: Rural+Urban | FC1: Rural | FD1: Urban | FE1: Rural+Urban | FF1: Rural | FG1: Urban | FH1: Rural+Urban | FI1: Rural | FJ1: Urban | FK1: Rural+Urban | FL1: Rural | FM1: Urban | FN1: Rural+Urban | FO1: Rural | FP1: Urban | FQ1: Rural+Urban | FR1: Rural | FS1: Urban | FT1: Rural+Urban | FU1: Rural | FV1: Urban | FW1: Rural+Urban | FX1: Rural | FY1: Urban | FZ1: Rural+Urban | GA1: Rural | GB1: Urban | GC1: Rural+Urban | GD1: Rural | GE1: Urban | GF1: Rural+Urban | GG1: Rural | GH1: Urban | GI1: Rural+Urban | GJ1: Rural | GK1: Urban | GL1: Rural+Urban | GM1: Rural | GN1: Urban | GO1: Rural+Urban | GP1: Rural | GQ1: Urban | GR1: Rural+Urban | GS1: Rural | GT1: Urban | GU1: Rural+Urban | GV1: Rural | GW1: Urban | GX1: Rural+Urban | GY1: Rural | GZ1: Urban | HA1: Rural+Urban | HB1: Rural | HC1: Urban | HD1: Rural+Urban | HE1: Rural | HF1: Urban | HG1: Rural+Urban | HH1: Rural | HI1: Urban | HJ1: Rural+Urban | HK1: Rural | HL1: Urban | HM1: Rural+Urban | HN1: Rural | HO1: Urban | HP1: Rural+Urban | HQ1: Rural | HR1: Urban | HS1: Rural+Urban | HT1: Rural | HU1: Urban | HV1: Rural+Urban | HW1: Rural | HX1: Urban | HY1: Rural+Urban | HZ1: Rural | IA1: Urban | IB1: Rural+Urban | IC1: Rural | ID1: Urban | IE1: Rural+Urban | IF1: Rural | IG1: Urban | IH1: Rural+Urban | II1: Rural | IJ1: Urban | IK1: Rural+Urban | IL1: Rural | IM1: Urban | IN1: Rural+Urban | IO1: Rural | IP1: Urban | IQ1: Rural+Urban | IR1: Rural | IS1: Urban | IT1: Rural+Urban | IU1: Rural | IV1: Urban | IW1: Rural+Urban | IX1: Rural | IY1: Urban | IZ1: Rural+Urban | JA1: Rural | JB1: Urban | JC1: Rural+Urban | JD1: Rural | JE1: Urban | JF1: Rural+Urban | JG1: Rural | JH1: Urban | JI1: Rural+Urban | JJ1: Rural | JK1: Urban | JL1: Rural+Urban | JM1: Rural | JN1: Urban | JO1: Rural+Urban | JP1: Rural | JQ1: Urban | JR1: Rural+Urban | JS1: Rural | JT1: Urban | JU1: Rural+Urban | JV1: Rural | JW1: Urban | JX1: Rural+Urban | JY1: Rural | JZ1: Urban | KA1: Rural+Urban | KB1: Rural | KC1: Urban | KD1: Rural+Urban | KE1: Rural | KF1: Urban | KG1: Rural+Urban | KH1: Rural | KI1: Urban | KJ1: Rural+Urban | KK1: Rural | KL1: Urban | KM1: Rural+Urban | KN1: Rural | KO1: Urban | KP1: Rural+Urban | KQ1: Rural | KR1: Urban | KS1: Rural+Urban | KT1: Rural | KU1: Urban | KV1: Rural+Urban | KW1: Rural | KX1: Urban | KY1: Rural+Urban | KZ1: Rural | LA1: Urban | LB1: Rural+Urban | LC1: Rural | LD1: Urban | LE1: Rural+Urban | LF1: Rural | LG1: Urban | LH1: Rural+Urban | LI1: Rural | LJ1: Urban | LK1: Rural+Urban | LL1: Rural | LM1: Urban | LN1: Rural+Urban | LO1: Rural | LP1: Urban | LQ1: Rural+Urban | LR1: Rural | LS1: Urban | LT1: Rural+Urban | LU1: Rural | LV1: Urban | LW1: Rural+Urban | LX1: Rural | LY1: Urban | LZ1: Rural+Urban | MA1: Rural | MB1: Urban | MC1: Rural+Urban | MD1: Rural | ME1: Urban | MF1: Rural+Urban | MG1: Rural | MH1: Urban | MI1: Rural+Urban | MJ1: Rural | MK1: Urban | ML1: Rural+Urban | MM1: Rural | MN1: Urban | MO1: Rural+Urban | MP1: Rural | MQ1: Urban | MR1: Rural+Urban | MS1: Rural | MT1: Urban | MU1: Rural+Urban | MV1: Rural | MW1: Urban | MX1: Rural+Urban | MY1: Rural | MZ1: Urban | NA1: Rural+Urban | NB1: Rural | NC1: Urban | ND1: Rural+Urban | NE1: Rural | NF1: Urban | NG1: Rural+Urban | NH1: Rural | NI1: Urban | NJ1: Rural+Urban
A2: Year | C2: 2013 | D2: 2013 | E2: 2013 | F2: 2013 | G2: 2013 | H2: 2013 | I2: 2013 | J2: 2013 | K2: 2013 | L2: 2013 | M2: 2013 | N2: 2013 | O2: 2013 | P2: 2013 | Q2: 2013 | R2: 2013 | S2: 2013 | T2: 2013 | U2: 2013 | V2: 2013 | W2: 2013 | X2: 2013 | Y2: 2013 | Z2: 2013 | AA2: 2013 | AB2: 2013 | AC2: 2013 | AD2: 2013 | AE2: 2013 | AF2: 2013 | AG2: 2013 | AH2: 2013 | AI2: 2013 | AJ2: 2013 | AK2: 2013 | AL2: 2013 | AM2: 2014 | AN2: 2014 | AO2: 2014 | AP2: 2014 | AQ2: 2014 | AR2: 2014 | AS2: 2014 | AT2: 2014 | AU2: 2014 | AV2: 2014 | AW2: 2014 | AX2: 2014 | AY2: 2014 | AZ2: 2014 | BA2: 2014 | BB2: 2014 | BC2: 2014 | BD2: 2014 | BE2: 2014 | BF2: 2014 | BG2: 2014 | BH2: 2014 | BI2: 2014 | BJ2: 2014 | BK2: 2014 | BL2: 2014 | BM2: 2014 | BN2: 2014 | BO2: 2014 | BP2: 2014 | BQ2: 2014 | BR2: 2014 | BS2: 2014 | BT2: 2014 | BU2: 2014 | BV2: 2014 | BW2: 2015 | BX2: 2015 | BY2: 2015 | BZ2: 2015 | CA2: 2015 | CB2: 2015 | CC2: 2015 | CD2: 2015 | CE2: 2015 | CF2: 2015 | CG2: 2015 | CH2: 2015 | CI2: 2015 | CJ2: 2015 | CK2: 2015 | CL2: 2015 | CM2: 2015 | CN2: 2015 | CO2: 2015 | CP2: 2015 | CQ2: 2015 | CR2: 2015 | CS2: 2015 | CT2: 2015 | CU2: 2015 | CV2: 2015 | CW2: 2015 | CX2: 2015 | CY2: 2015 | CZ2: 2015 | DA2: 2015 | DB2: 2015 | DC2: 2015 | DD2: 2015 | DE2: 2015 | DF2: 2015 | DG2: 2016 | DH2: 2016 | DI2: 2016 | DJ2: 2016 | DK2: 2016 | DL2: 2016 | DM2: 2016 | DN2: 2016 | DO2: 2016 | DP2: 2016 | DQ2: 2016 | DR2: 2016 | DS2: 2016 | DT2: 2016 | DU2: 2016 | DV2: 2016 | DW2: 2016 | DX2: 2016 | DY2: 2016 | DZ2: 2016 | EA2: 2016 | EB2: 2016 | EC2: 2016 | ED2: 2016 | EE2: 2016 | EF2: 2016 | EG2: 2016 | EH2: 2016 | EI2: 2016 | EJ2: 2016 | EK2: 2016 | EL2: 2016 | EM2: 2016 | EN2: 2016 | EO2: 2016 | EP2: 2016 | EQ2: 2017 | ER2: 2017 | ES2: 2017 | ET2: 2017 | EU2: 2017 | EV2: 2017 | EW2: 2017 | EX2: 2017 | EY2: 2017 | EZ2: 2017 | FA2: 2017 | FB2: 2017 | FC2: 2017 | FD2: 2017 | FE2: 2017 | FF2: 2017 | FG2: 2017 | FH2: 2017 | FI2: 2017 | FJ2: 2017 | FK2: 2017 | FL2: 2017 | FM2: 2017 | FN2: 2017 | FO2: 2017 | FP2: 2017 | FQ2: 2017 | FR2: 2017 | FS2: 2017 | FT2: 2017 | FU2: 2017 | FV2: 2017 | FW2: 2017 | FX2: 2017 | FY2: 2017 | FZ2: 2017 | GA2: 2018 | GB2: 2018 | GC2: 2018 | GD2: 2018 | GE2: 2018 | GF2: 2018 | GG2: 2018 | GH2: 2018 | GI2: 2018 | GJ2: 2018 | GK2: 2018 | GL2: 2018 | GM2: 2018 | GN2: 2018 | GO2: 2018 | GP2: 2018 | GQ2: 2018 | GR2: 2018 | GS2: 2018 | GT2: 2018 | GU2: 2018 | GV2: 2018 | GW2: 2018 | GX2: 2018 | GY2: 2018 | GZ2: 2018 | HA2: 2018 | HB2: 2018 | HC2: 2018 | HD2: 2018 | HE2: 2018 | HF2: 2018 | HG2: 2018 | HH2: 2018 | HI2: 2018 | HJ2: 2018 | HK2: 2019 | HL2: 2019 | HM2: 2019 | HN2: 2019 | HO2: 2019 | HP2: 2019 | HQ2: 2019 | HR2: 2019 | HS2: 2019 | HT2: 2019 | HU2: 2019 | HV2: 2019 | HW2: 2019 | HX2: 2019 | HY2: 2019 | HZ2: 2019 | IA2: 2019 | IB2: 2019 | IC2: 2019 | ID2: 2019 | IE2: 2019 | IF2: 2019 | IG2: 2019 | IH2: 2019 | II2: 2019 | IJ2: 2019 | IK2: 2019 | IL2: 2019 | IM2: 2019 | IN2: 2019 | IO2: 2019 | IP2: 2019 | IQ2: 2019 | IR2: 2020 | IS2: 2020 | IT2: 2020 | IU2: 2020 | IV2: 2020 | IW2: 2020 | IX2: 2020 | IY2: 2020 | IZ2: 2020 | JA2: 2020 | JB2: 2020 | JC2: 2020 | JD2: 2020 | JE2: 2020 | JF2: 2020 | JG2: 2020 | JH2: 2020 | JI2: 2020 | JJ2: 2020 | JK2: 2020 | JL2: 2020 | JM2: 2020 | JN2: 2020 | JO2: 2020 | JP2: 2020 | JQ2: 2020 | JR2: 2020 | JS2: 2020 | JT2: 2020 | JU2: 2020 | JV2: 2020 | JW2: 2020 | JX2: 2020 | JY2: 2020 | JZ2: 2020 | KA2: 2020 | KB2: 2021 | KC2: 2021 | KD2: 2021 | KE2: 2021 | KF2: 2021 | KG2: 2021 | KH2: 2021 | KI2: 2021 | KJ2: 2021 | KK2: 2021 | KL2: 2021 | KM2: 2021 | KN2: 2021 | KO2: 2021 | KP2: 2021 | KQ2: 2021 | KR2: 2021 | KS2: 2021 | KT2: 2021 | KU2: 2021 | KV2: 2021 | KW2: 2021 | KX2: 2021 | KY2: 2021 | KZ2: 2021 | LA2: 2021 | LB2: 2021 | LC2: 2021 | LD2: 2021 | LE2: 2021 | LF2: 2021 | LG2: 2021 | LH2: 2021 | LI2: 2021 | LJ2: 2021 | LK2: 2021 | LL2: 2022 | LM2: 2022 | LN2: 2022 | LO2: 2022 | LP2: 2022 | LQ2: 2022 | LR2: 2022 | LS2: 2022 | LT2: 2022 | LU2: 2022 | LV2: 2022 | LW2: 2022 | LX2: 2022 | LY2: 2022 | LZ2: 2022 | MA2: 2022 | MB2: 2022 | MC2: 2022 | MD2: 2022 | ME2: 2022 | MF2: 2022 | MG2: 2022 | MH2: 2022 | MI2: 2022 | MJ2: 2022 | MK2: 2022 | ML2: 2022 | MM2: 2022 | MN2: 2022 | MO2: 2022 | MP2: 2022 | MQ2: 2022 | MR2: 2022 | MS2: 2022 | MT2: 2022 | MU2: 2022 | MV2: 2023 | MW2: 2023 | MX2: 2023 | MY2: 2023 | MZ2: 2023 | NA2: 2023 | NB2: 2023 | NC2: 2023 | ND2: 2023 | NE2: 2023 | NF2: 2023 | NG2: 2023 | NH2: 2023 | NI2: 2023 | NJ2: 2023
A3: Month | C3: January | D3: January | E3: January | F3: February | G3: February | H3: February | I3: March | J3: March | K3: March | L3: April | M3: April | N3: April | O3: May | P3: May | Q3: May | R3: June | S3: June | T3: June | U3: July | V3: July | W3: July | X3: August | Y3: August | Z3: August | AA3: September | AB3: September | AC3: September | AD3: October | AE3: October | AF3: October | AG3: November | AH3: November | AI3: November | AJ3: December | AK3: December | AL3: December | AM3: January | AN3: January | AO3: January | AP3: February | AQ3: February | AR3: February | AS3: March | AT3: March | AU3: Marcrh | AV3: April | AW3: April | AX3: April | AY3: May | AZ3: May | BA3: May | BB3: June | BC3: June | BD3: June | BE3: July | BF3: July | BG3: July | BH3: August | BI3: August | BJ3: August | BK3: September | BL3: September | BM3: September | BN3: October | BO3: October | BP3: October | BQ3: November | BR3: November | BS3: November | BT3: December | BU3: December | BV3: December | BW3: January | BX3: January | BY3: January | BZ3: February | CA3: February | CB3: February | CC3: March | CD3: March | CE3: March | CF3: April | CG3: April | CH3: April | CI3: May | CJ3: May | CK3: May | CL3: June | CM3: June | CN3: June | CO3: July | CP3: July | CQ3: July | CR3: August | CS3: August | CT3: August | CU3: September | CV3: September | CW3: September | CX3: October | CY3: October | CZ3: October | DA3: November | DB3: November | DC3: November | DD3: December | DE3: December | DF3: December | DG3: January | DH3: January | DI3: January | DJ3: February | DK3: February | DL3: February | DM3: March | DN3: March | DO3: March | DP3: April | DQ3: April | DR3: April | DS3: May | DT3: May | DU3: May | DV3: June | DW3: June | DX3: June | DY3: July | DZ3: July | EA3: July | EB3: August | EC3: August | ED3: August | EE3: September | EF3: September | EG3: September | EH3: October | EI3: October | EJ3: October | EK3: November | EL3: November | EM3: November | EN3: December | EO3: December | EP3: December | EQ3: January | ER3: January | ES3: January | ET3: February | EU3: February | EV3: February | EW3: March | EX3: March | EY3: March | EZ3: April | FA3: April | FB3: April | FC3: May | FD3: May | FE3: May | FF3: June | FG3: June | FH3: June | FI3: July | FJ3: July | FK3: July | FL3: August | FM3: August | FN3: August | FO3: September | FP3: September | FQ3: September | FR3: October | FS3: October | FT3: October | FU3: November | FV3: November | FW3: November | FX3: December | FY3: December | FZ3: December | GA3: January | GB3: January | GC3: January | GD3: February | GE3: February | GF3: February | GG3: March | GH3: March | GI3: March | GJ3: April | GK3: April | GL3: April | GM3: May | GN3: May | GO3: May | GP3: June | GQ3: June | GR3: June | GS3: July | GT3: July | GU3: July | GV3: August | GW3: August | GX3: August | GY3: September | GZ3: September | HA3: September | HB3: October | HC3: October | HD3: October | HE3: November | HF3: November | HG3: November | HH3: December | HI3: December | HJ3: December | HK3: January | HL3: January | HM3: January | HN3: February | HO3: February | HP3: February | HQ3: March | HR3: March | HS3: March | HT3: May | HU3: May | HV3: May | HW3: June | HX3: June | HY3: June | HZ3: July | IA3: July | IB3: July | IC3: August | ID3: August | IE3: August | IF3: September | IG3: September | IH3: September | II3: October | IJ3: October | IK3: October | IL3: November | IM3: November | IN3: November | IO3: December | IP3: December | IQ3: December | IR3: January | IS3: January | IT3: January | IU3: February | IV3: February | IW3: February | IX3: March | IY3: March | IZ3: March | JA3: April | JB3: April | JC3: April | JD3: May | JE3: May | JF3: May | JG3: June | JH3: June | JI3: June | JJ3: July | JK3: July | JL3: July | JM3: August | JN3: August | JO3: August | JP3: September | JQ3: September | JR3: September | JS3: October | JT3: October | JU3: October | JV3: November | JW3: November | JX3: November | JY3: December | JZ3: December | KA3: December | KB3: January | KC3: January | KD3: January | KE3: February | KF3: February | KG3: February | KH3: March | KI3: March | KJ3: March | KK3: April | KL3: April | KM3: April | KN3: May | KO3: May | KP3: May | KQ3: June | KR3: June | KS3: June | KT3: July | KU3: July | KV3: July | KW3: August | KX3: August | KY3: August | KZ3: September | LA3: September | LB3: September | LC3: October | LD3: October | LE3: October | LF3: November | LG3: November | LH3: November | LI3: December | LJ3: December | LK3: December | LL3: January | LM3: January | LN3: January | LO3: February | LP3: February | LQ3: February | LR3: March | LS3: March | LT3: March | LU3: April | LV3: April | LW3: April | LX3: May | LY3: May | LZ3: May | MA3: June | MB3: June | MC3: June | MD3: July | ME3: July | MF3: July | MG3: August | MH3: August | MI3: August | MJ3: September | MK3: September | ML3: September | MM3: October | MN3: October | MO3: October | MP3: November | MQ3: November | MR3: November | MS3: December | MT3: December | MU3: December | MV3: January | MW3: January | MX3: January | MY3: February | MZ3: February | NA3: February | NB3: March | NC3: March | ND3: March | NE3: April | NF3: April | NG3: April | NH3: May | NI3: May | NJ3: May
A4: Cereals and products | B4: =VLOOKUP(A4, NOTES!C5:D30, 2,0) -> Food | C4: 107.5 | D4: 110.5 | E4: 108.4 | F4: 109.2 | G4: 112.9 | H4: 110.4 | I4: 110.2 | J4: 113.9 | K4: 111.4 | L4: 110.2 | M4: 114.6 | N4: 111.6 | O4: 110.9 | P4: 115.4 | Q4: 112.3 | R4: 112.3 | S4: 117 | T4: 113.8 | U4: 113.4 | V4: 117.8 | W4: 114.8 | X4: 114.3 | Y4: 118.3 | Z4: 115.6 | AA4: 115.4 | AB4: 118.6 | AC4: 116.4 | AD4: 116.3 | AE4: 118.9 | AF4: 117.1 | AG4: 117.3 | AH4: 119.8 | AI4: 118.1 | AJ4: 118.4 | AK4: 120.5 | AL4: 119.1 | AM4: 118.9 | AN4: 121.2 | AO4: 119.6 | AP4: 119.4 | AQ4: 121.9 | AR4: 120.2 | AS4: 120.1 | AT4: 122.1 | AU4: 120.7 | AV4: 120.2 | AW4: 122.5 | AX4: 120.9 | AY4: 120.3 | AZ4: 122.7 | BA4: 121.1 | BB4: 120.7 | BC4: 123.1 | BD4: 121.5 | BE4: 121.7 | BF4: 123.8 | BG4: 122.4 | BH4: 121.8 | BI4: 124.8 | BJ4: 122.7 | BK4: 122.3 | BL4: 124.2 | BM4: 122.9 | BN4: 122.6 | BO4: 124.6 | BP4: 123.2 | BQ4: 122.7 | BR4: 124.5 | BS4: 123.3 | BT4: 122.4 | BU4: 124 | BV4: 122.9 | BW4: 123.1 | BX4: 124 | BY4: 123.4 | BZ4: 123.4 | CA4: 124.3 | CB4: 123.7 | CC4: 123.3 | CD4: 124 | CE4: 123.5 | CF4: 123.3 | CG4: 123.8 | CH4: 123.5 | CI4: 123.5 | CJ4: 123.8 | CK4: 123.6 | CL4: 124.1 | CM4: 123.6 | CN4: 123.9 | CO4: 124 | CP4: 123.2 | CQ4: 123.7 | CR4: 124.7 | CS4: 123.1 | CT4: 124.2 | CU4: 125.1 | CV4: 123.4 | CW4: 124.6 | CX4: 125.6 | CY4: 123.6 | CZ4: 125 | DA4: 126.1 | DB4: 124 | DC4: 125.4 | DD4: 126.3 | DE4: 124.3 | DF4: 125.7 | DG4: 126.8 | DH4: 124.7 | DI4: 126.1 | DJ4: 127.1 | DK4: 124.8 | DL4: 126.4 | DM4: 127.3 | DN4: 124.8 | DO4: 126.5 | DP4: 127.4 | DQ4: 124.9 | DR4: 126.6 | DS4: 127.6 | DT4: 125 | DU4: 126.8 | DV4: 128.6 | DW4: 125.9 | DX4: 127.7 | DY4: 129.3 | DZ4: 126.8 | EA4: 128.5 | EB4: 130.1 | EC4: 127.6 | ED4: 129.3 | EE4: 130.8 | EF4: 128.1 | EG4: 129.9 | EH4: 131.3 | EI4: 128.7 | EJ4: 130.5 | EK4: 132 | EL4: 130.2 | EM4: 131.4 | EN4: 132.6 | EO4: 131.6 | EP4: 132.3 | EQ4: 133.1 | ER4: 132.2 | ES4: 132.8 | ET4: 133.3 | EU4: 132.8 | EV4: 133.1 | EW4: 133.6 | EX4: 132.7 | EY4: 133.3 | EZ4: 133.2 | FA4: 132.7 | FB4: 133 | FC4: 133.1 | FD4: 132.6 | FE4: 132.9 | FF4: 133.5 | FG4: 132.9 | FH4: 133.3 | FI4: 134 | FJ4: 132.8 | FK4: 133.6 | FL4: 134.8 | FM4: 133.2 | FN4: 134.3 | FO4: 135.2 | FP4: 133.6 | FQ4: 134.7 | FR4: 135.9 | FS4: 133.9 | FT4: 135.3 | FU4: 136.3 | FV4: 134.3 | FW4: 135.7 | FX4: 136.4 | FY4: 134.4 | FZ4: 135.8 | GA4: 136.6 | GB4: 134.6 | GC4: 136 | GD4: 136.4 | GE4: 134.8 | GF4: 135.9 | GG4: 136.8 | GH4: 135 | GI4: 136.2 | GJ4: 137.1 | GK4: 135 | GL4: 136.4 | GM4: 137.4 | GN4: 135 | GO4: 136.6 | GP4: 137.6 | GQ4: 135.3 | GR4: 136.9 | GS4: 138.4 | GT4: 135.6 | GU4: 137.5 | GV4: 139.2 | GW4: 136.5 | GX4: 138.3 | GY4: 139.4 | GZ4: 137 | HA4: 138.6 | HB4: 139.3 | HC4: 137.6 | HD4: 137.4 | HE4: 137.1 | HF4: 138.1 | HG4: 137.4 | HH4: 137.1 | HI4: 138.5 | HJ4: 137.5 | HK4: 136.6 | HL4: 138.3 | HM4: 137.1 | HN4: 136.8 | HO4: 139.4 | HP4: 137.6 | HQ4: 136.9 | HR4: 139.7 | HS4: 137.8 | HT4: 137.4 | HU4: 140.4 | HV4: 138.3 | HW4: 137.8 | HX4: 140.7 | HY4: 138.7 | HZ4: 138.4 | IA4: 141.4 | IB4: 139.3 | IC4: 139.2 | ID4: 142.1 | IE4: 140.1 | IF4: 140.1 | IG4: 142.7 | IH4: 140.9 | II4: 141 | IJ4: 143.5 | IK4: 141.8 | IL4: 141.8 | IM4: 144.1 | IN4: 142.5 | IO4: 142.8 | IP4: 144.9 | IQ4: 143.5 | IR4: 143.7 | IS4: 145.6 | IT4: 144.3 | IU4: 144.2 | IV4: 146.2 | IW4: 144.8 | IX4: 144.4 | IY4: 146.5 | IZ4: 145.1 | JA4: 147.2 | JB4: 151.8 | JC4: 148.7 | JD4: NA | JE4: NA | JF4: NA | JG4: 148.2 | JH4: 152.7 | JI4: 149.6 | JJ4: 148.2 | JK4: 152.7 | JL4: 149.6 | JM4: 147.6 | JN4: 151.6 | JO4: 148.9 | JP4: 146.9 | JQ4: 151.5 | JR4: 148.4 | JS4: 146 | JT4: 150.6 | JU4: 147.5 | JV4: 145.4 | JW4: 149.7 | JX4: 146.8 | JY4: 144.6 | JZ4: 149 | KA4: 146 | KB4: 143.4 | KC4: 148 | KD4: 144.9 | KE4: 142.8 | KF4: 147.6 | KG4: 144.3 | KH4: 142.5 | KI4: 147.5 | KJ4: 144.1 | KK4: 142.7 | KL4: 147.6 | KM4: 144.3 | KN4: 145.1 | KO4: 148.8 | KP4: 146.3 | KQ4: 145.6 | KR4: 149.2 | KS4: 146.7 | KT4: 145.1 | KU4: 149.1 | KV4: 146.4 | KW4: 144.9 | KX4: 149.3 | KY4: 146.6 | KZ4: 145.4 | LA4: 149.3 | LB4: 146.6 | LC4: 146.1 | LD4: 150.1 | LE4: 147.4 | LF4: 146.9 | LG4: 151 | LH4: 148.2 | LI4: 147.4 | LJ4: 151.6 | LK4: 148.7 | LL4: 148.3 | LM4: 152.2 | LN4: 149.5 | LO4: 148.8 | LP4: 152.5 | LQ4: 150 | LR4: 150.2 | LS4: 153.7 | LT4: 151.3 | LU4: 151.8 | LV4: 155.4 | LW4: 152.9 | LX4: 152.9 | LY4: 156.7 | LZ4: 154.1 | MA4: 153.8 | MB4: 157.5 | MC4: 155 | MD4: 155.2 | ME4: 159.3 | MF4: 156.5 | MG4: 159.5 | MH4: 162.1 | MI4: 160.3 | MJ4: 162.9 | MK4: 164.9 | ML4: 163.5 | MM4: 164.7 | MN4: 166.4 | MO4: 165.2 | MP4: 166.9 | MQ4: 168.4 | MR4: 167.4 | MS4: 168.8 | MT4: 170.2 | MU4: 169.2 | MV4: 174 | MW4: 173.3 | MX4: 173.8 | MY4: 174.2 | MZ4: 174.7 | NA4: 174.4 | NB4: 174.3 | NC4: 174.7 | ND4: 174.4 | NE4: 173.3 | NF4: 174.8 | NG4: 173.8 | NH4: 173.2 | NI4: 174.7 | NJ4: 173.7
A5: Meat and fish | B5: =VLOOKUP(A5, NOTES!C6:D31, 2,0) -> Food | C5: 106.3 | D5: 109.1 | E5: 107.3 | F5: 108.7 | G5: 112.9 | H5: 110.2 | I5: 108.8 | J5: 111.4 | K5: 109.7 | L5: 109.5 | M5: 113.4 | N5: 110.9 | O5: 109.8 | P5: 114.2 | Q5: 111.3 | R5: 112.1 | S5: 120.1 | T5: 114.9 | U5: 114.9 | V5: 119.2 | W5: 116.4 | X5: 115.4 | Y5: 120.4 | Z5: 117.2 | AA5: 115.7 | AB5: 119.1 | AC5: 116.9 | AD5: 115.4 | AE5: 118.1 | AF5: 116.3 | AG5: 114.9 | AH5: 116.3 | AI5: 115.4 | AJ5: 115.9 | AK5: 118.1 | AL5: 116.7 | AM5: 117.1 | AN5: 122 | AO5: 118.8 | AP5: 117.7 | AQ5: 122 | AR5: 119.2 | AS5: 118.1 | AT5: 121.4 | AU5: 119.3 | AV5: 118.9 | AW5: 121.7 | AX5: 119.9 | AY5: 120.2 | AZ5: 124.1 | BA5: 121.6 | BB5: 121.6 | BC5: 125.9 | BD5: 123.1 | BE5: 122.5 | BF5: 126.4 | BG5: 123.9 | BH5: 122.8 | BI5: 127.3 | BJ5: 124.4 | BK5: 122.4 | BL5: 125.4 | BM5: 123.5 | BN5: 122.5 | BO5: 126.1 | BP5: 123.8 | BQ5: 122.6 | BR5: 125.6 | BS5: 123.7 | BT5: 122.4 | BU5: 124.7 | BV5: 123.2 | BW5: 123.1 | BX5: 125.5 | BY5: 123.9 | BZ5: 124.4 | CA5: 126.5 | CB5: 125.1 | CC5: 124.7 | CD5: 126.7 | CE5: 125.4 | CF5: 125.5 | CG5: 128.2 | CH5: 126.4 | CI5: 127.1 | CJ5: 129.7 | CK5: 128 | CL5: 130.4 | CM5: 134.4 | CN5: 131.8 | CO5: 131.5 | CP5: 134.3 | CQ5: 132.5 | CR5: 131.3 | CS5: 131.7 | CT5: 131.4 | CU5: 131.1 | CV5: 129 | CW5: 130.4 | CX5: 130.4 | CY5: 128.6 | CZ5: 129.8 | DA5: 130.6 | DB5: 129.8 | DC5: 130.3 | DD5: 131.3 | DE5: 131.7 | DF5: 131.4 | DG5: 133.2 | DH5: 135.9 | DI5: 134.1 | DJ5: 133.7 | DK5: 135.1 | DL5: 134.2 | DM5: 134.4 | DN5: 136.3 | DO5: 135.1 | DP5: 135.4 | DQ5: 139.3 | DR5: 136.8 | DS5: 137.5 | DT5: 142.1 | DU5: 139.1 | DV5: 138.6 | DW5: 143.9 | DX5: 140.5 | DY5: 139.5 | DZ5: 144.2 | EA5: 141.2 | EB5: 138.8 | EC5: 140.3 | ED5: 139.3 | EE5: 138.2 | EF5: 137.7 | EG5: 138 | EH5: 137.6 | EI5: 138.4 | EJ5: 137.9 | EK5: 137.4 | EL5: 138.5 | EM5: 137.8 | EN5: 137.3 | EO5: 138.2 | EP5: 137.6 | EQ5: 137.8 | ER5: 138.9 | ES5: 138.2 | ET5: 138.3 | EU5: 139.8 | EV5: 138.8 | EW5: 138.8 | EX5: 139.4 | EY5: 139 | EZ5: 138.7 | FA5: 140.6 | FB5: 139.4 | FC5: 140.3 | FD5: 144.1 | FE5: 141.6 | FF5: 143.7 | FG5: 148.7 | FH5: 145.5 | FI5: 144.2 | FJ5: 148.4 | FK5: 145.7 | FL5: 143.1 | FM5: 143.9 | FN5: 143.4 | FO5: 142 | FP5: 143 | FQ5: 142.4 | FR5: 141.9 | FS5: 142.8 | FT5: 142.2 | FU5: 142.5 | FV5: 142.1 | FW5: 142.4 | FX5: 143.7 | FY5: 142.6 | FZ5: 143.3 | GA5: 144.4 | GB5: 143.7 | GC5: 144.2 | GD5: 143.7 | GE5: 143 | GF5: 143.5 | GG5: 143.8 | GH5: 143.1 | GI5: 143.6 | GJ5: 144.5 | GK5: 144.3 | GL5: 144.4 | GM5: 145.7 | GN5: 148.2 | GO5: 146.6 | GP5: 148.1 | GQ5: 149.7 | GR5: 148.7 | GS5: 149.3 | GT5: 148.6 | GU5: 149.1 | GV5: 148.8 | GW5: 146.4 | GX5: 148 | GY5: 147.2 | GZ5: 143.1 | HA5: 145.8 | HB5: 147.6 | HC5: 144.9 | HD5: 149.5 | HE5: 150.8 | HF5: 146.3 | HG5: 149.2 | HH5: 151.9 | HI5: 147.8 | HJ5: 150.5 | HK5: 152.5 | HL5: 149.4 | HM5: 151.4 | HN5: 153 | HO5: 150.1 | HP5: 152 | HQ5: 154.1 | HR5: 151.1 | HS5: 153 | HT5: 159.5 | HU5: 156.7 | HV5: 158.5 | HW5: 163.5 | HX5: 159.6 | HY5: 162.1 | HZ5: 164 | IA5: 160.2 | IB5: 162.7 | IC5: 161.9 | ID5: 158.3 | IE5: 160.6 | IF5: 161.9 | IG5: 158.7 | IH5: 160.8 | II5: 161.6 | IJ5: 159.8 | IK5: 161 | IL5: 163.7 | IM5: 162.4 | IN5: 163.2 | IO5: 165.3 | IP5: 164.5 | IQ5: 165 | IR5: 167.3 | IS5: 167.6 | IT5: 167.4 | IU5: 167.5 | IV5: 167.6 | IW5: 167.5 | IX5: 166.8 | IY5: 167.5 | IZ5: 167 | JA5: NA | JB5: NA | JC5: NA | JD5: NA | JE5: NA | JF5: NA | JG5: 190.3 | JH5: 197 | JI5: 192.7 | JJ5: 190.3 | JK5: 197 | JL5: 192.7 | JM5: 187.2 | JN5: 197.8 | JO5: 190.9 | JP5: 183.9 | JQ5: 193.1 | JR5: 187.1 | JS5: 186.3 | JT5: 193.7 | JU5: 188.9 | JV5: 188.6 | JW5: 195.5 | JX5: 191 | JY5: 188.5 | JZ5: 195.7 | KA5: 191 | KB5: 187.5 | KC5: 194.8 | KD5: 190.1 | KE5: 184 | KF5: 191.2 | KG5: 186.5 | KH5: 189.4 | KI5: 197.5 | KJ5: 192.2 | KK5: 195.5 | KL5: 202.5 | KM5: 198 | KN5: 198.5 | KO5: 204.3 | KP5: 200.5 | KQ5: 200.1 | KR5: 205.5 | KS5: 202 | KT5: 204.5 | KU5: 210.9 | KV5: 206.8 | KW5: 202.3 | KX5: 207.4 | KY5: 204 | KZ5: 202.1 | LA5: 207.4 | LB5: 204 | LC5: 202.5 | LD5: 208.4 | LE5: 204.6 | LF5: 199.8 | LG5: 204.9 | LH5: 201.6 | LI5: 197 | LJ5: 202.2 | LK5: 198.8 | LL5: 196.9 | LM5: 202.1 | LN5: 198.7 | LO5: 198.1 | LP5: 205.2 | LQ5: 200.6 | LR5: 208 | LS5: 215.8 | LT5: 210.7 | LU5: 209.7 | LV5: 215.8 | LW5: 211.8 | LX5: 214.7 | LY5: 221.2 | LZ5: 217 | MA5: 217.2 | MB5: 223.4 | MC5: 219.4 | MD5: 210.8 | ME5: 217.1 | MF5: 213 | MG5: 204.1 | MH5: 210.9 | MI5: 206.5 | MJ5: 206.7 | MK5: 213.7 | ML5: 209.2 | MM5: 208.8 | MN5: 214.9 | MO5: 210.9 | MP5: 207.2 | MQ5: 213.4 | MR5: 209.4 | MS5: 206.9 | MT5: 212.9 | MU5: 209 | MV5: 208.3 | MW5: 215.2 | MX5: 210.7 | MY5: 205.2 | MZ5: 212.2 | NA5: 207.7 | NB5: 205.2 | NC5: 212.2 | ND5: 207.7 | NE5: 206.9 | NF5: 213.7 | NG5: 209.3 | NH5: 211.5 | NI5: 219.4 | NJ5: 214.3
A6: Egg | B6: =VLOOKUP(A6, NOTES!C7:D32, 2,0) -> Food | C6: 108.1 | D6: 113 | E6: 110 | F6: 110.2 | G6: 116.9 | H6: 112.8 | I6: 109.9 | J6: 113.2 | K6: 111.2 | L6: 106.9 | M6: 106 | N6: 106.6 | O6: 105.9 | P6: 102.7 | Q6: 104.7 | R6: 108.1 | S6: 112.5 | T6: 109.8 | U6: 110.5 | V6: 114 | W6: 111.9 | X6: 111.1 | Y6: 112.7 | Z6: 111.7 | AA6: 111.7 | AB6: 113.2 | AC6: 112.3 | AD6: 112.6 | AE6: 114.5 | AF6: 113.3 | AG6: 116.2 | AH6: 122.6 | AI6: 118.7 | AJ6: 120.4 | AK6: 128.5 | AL6: 123.5 | AM6: 120.5 | AN6: 129.9 | AO6: 124.1 | AP6: 121.2 | AQ6: 124.5 | AR6: 122.5 | AS6: 120.7 | AT6: 121.5 | AU6: 121 | AV6: 118.1 | AW6: 113.3 | AX6: 116.2 | AY6: 116.9 | AZ6: 114.2 | BA6: 115.9 | BB6: 116.1 | BC6: 115.4 | BD6: 115.8 | BE6: 117.7 | BF6: 118 | BG6: 117.8 | BH6: 117.8 | BI6: 116.5 | BJ6: 117.3 | BK6: 117.8 | BL6: 116.4 | BM6: 117.3 | BN6: 118.3 | BO6: 117.8 | BP6: 118.1 | BQ6: 119.9 | BR6: 122.7 | BS6: 121 | BT6: 121.8 | BU6: 126.3 | BV6: 123.5 | BW6: 122.1 | BX6: 126.6 | BY6: 123.8 | BZ6: 122.1 | CA6: 119.5 | CB6: 121.1 | CC6: 118.9 | CD6: 113.5 | CE6: 116.8 | CF6: 117.2 | CG6: 110 | CH6: 114.4 | CI6: 117.3 | CJ6: 111.3 | CK6: 115 | CL6: 122.1 | CM6: 120.9 | CN6: 121.6 | CO6: 122 | CP6: 119.5 | CQ6: 121 | CR6: 121.3 | CS6: 118.1 | CT6: 120.1 | CU6: 120.7 | CV6: 115.6 | CW6: 118.7 | CX6: 120.8 | CY6: 115.9 | CZ6: 118.9 | DA6: 121.7 | DB6: 121.5 | DC6: 121.6 | DD6: 123.3 | DE6: 127.1 | DF6: 124.8 | DG6: 126.5 | DH6: 132 | DI6: 128.6 | DJ6: 127.7 | DK6: 130.3 | DL6: 128.7 | DM6: 125.1 | DN6: 123.7 | DO6: 124.6 | DP6: 123.4 | DQ6: 119.9 | DR6: 122 | DS6: 124.4 | DT6: 127 | DU6: 125.4 | DV6: 126.6 | DW6: 130.9 | DX6: 128.3 | DY6: 129.6 | DZ6: 136.6 | EA6: 132.3 | EB6: 130.3 | EC6: 133.7 | ED6: 131.6 | EE6: 130.5 | EF6: 130.6 | EG6: 130.5 | EH6: 130.1 | EI6: 130.3 | EJ6: 130.2 | EK6: 130.6 | EL6: 134.1 | EM6: 132 | EN6: 131.6 | EO6: 134.9 | EP6: 132.9 | EQ6: 131.9 | ER6: 132.6 | ES6: 132.2 | ET6: 129.3 | EU6: 129.3 | EV6: 129.3 | EW6: 128.8 | EX6: 128.4 | EY6: 128.6 | EZ6: 127.1 | FA6: 124.5 | FB6: 126.1 | FC6: 126.8 | FD6: 125.6 | FE6: 126.3 | FF6: 128 | FG6: 128.3 | FH6: 128.1 | FI6: 129.8 | FJ6: 129.4 | FK6: 129.6 | FL6: 130 | FM6: 128.3 | FN6: 129.3 | FO6: 130.5 | FP6: 129.7 | FQ6: 130.2 | FR6: 131 | FS6: 131.4 | FT6: 131.2 | FU6: 140.5 | FV6: 146.7 | FW6: 142.9 | FX6: 144.8 | FY6: 145.9 | FZ6: 145.2 | GA6: 143.8 | GB6: 143.6 | GC6: 143.7 | GD6: 140.6 | GE6: 139.9 | GF6: 140.3 | GG6: 140 | GH6: 135.5 | GI6: 138.3 | GJ6: 135.9 | GK6: 130.8 | GL6: 133.9 | GM6: 135.5 | GN6: 130.5 | GO6: 133.6 | GP6: 136.7 | GQ6: 133.9 | GR6: 135.6 | GS6: 139.3 | GT6: 139.1 | GU6: 139.2 | GV6: 139.1 | GW6: 136.6 | GX6: 138.1 | GY6: 136.6 | GZ6: 132.8 | HA6: 135.1 | HB6: 134.6 | HC6: 133.5 | HD6: 137.3 | HE6: 136.7 | HF6: 137.8 | HG6: 137.1 | HH6: 137.4 | HI6: 141.1 | HJ6: 138.8 | HK6: 138.2 | HL6: 143.5 | HM6: 140.2 | HN6: 139.1 | HO6: 145.3 | HP6: 141.5 | HQ6: 138.7 | HR6: 142.9 | HS6: 140.3 | HT6: 134.5 | HU6: 138.3 | HV6: 136 | HW6: 136.2 | HX6: 140.4 | HY6: 137.8 | HZ6: 138.4 | IA6: 142.5 | IB6: 140 | IC6: 137.1 | ID6: 140.8 | IE6: 138.5 | IF6: 138.3 | IG6: 141.6 | IH6: 139.6 | II6: 141.2 | IJ6: 144.7 | IK6: 142.6 | IL6: 143.8 | IM6: 148.4 | IN6: 145.6 | IO6: 149.5 | IP6: 153.7 | IQ6: 151.1 | IR6: 153.5 | IS6: 157 | IT6: 154.9 | IU6: 150.9 | IV6: 153.1 | IW6: 151.8 | IX6: 147.6 | IY6: 148.9 | IZ6: 148.1 | JA6: 146.9 | JB6: 151.9 | JC6: 148.8 | JD6: NA | JE6: NA | JF6: NA | JG6: 149.4 | JH6: 154.6 | JI6: 151.4 | JJ6: 149.4 | JK6: 154.6 | JL6: 151.4 | JM6: 148.4 | JN6: 154.5 | JO6: 150.8 | JP6: 149.5 | JQ6: 157.3 | JR6: 152.5 | JS6: 159.2 | JT6: 164.8 | JU6: 161.4 | JV6: 171.6 | JW6: 176.9 | JX6: 173.6 | JY6: 173.4 | JZ6: 178.3 | KA6: 175.3 | KB6: 173.4 | KC6: 178.4 | KD6: 175.3 | KE6: 168 | KF6: 169.9 | KG6: 168.7 | KH6: 163.2 | KI6: 164.7 | KJ6: 163.8 | KK6: 163.4 | KL6: 166.4 | KM6: 164.6 | KN6: 168.6 | KO6: 173 | KP6: 170.3 | KQ6: 179.3 | KR6: 182.8 | KS6: 180.7 | KT6: 180.4 | KU6: 185 | KV6: 182.2 | KW6: 176.5 | KX6: 174.1 | KY6: 172.8 | KZ6: 172 | LA6: 174.1 | LB6: 172.8 | LC6: 170.1 | LD6: 173 | LE6: 171.2 | LF6: 171.5 | LG6: 175.4 | LH6: 173 | LI6: 176.5 | LJ6: 180 | LK6: 177.9 | LL6: 178 | LM6: 180.1 | LN6: 178.8 | LO6: 175.5 | LP6: 176.4 | LQ6: 175.8 | LR6: 167.9 | LS6: 167.7 | LT6: 167.8 | LU6: 164.5 | LV6: 164.6 | LW6: 164.5 | LX6: 161.4 | LY6: 164.1 | LZ6: 162.4 | MA6: 169.6 | MB6: 172.8 | MC6: 170.8 | MD6: 174.3 | ME6: 176.6 | MF6: 175.2 | MG6: 168.3 | MH6: 170.6 | MI6: 169.2 | MJ6: 169 | MK6: 170.9 | ML6: 169.7 | MM6: 170.3 | MN6: 171.9 | MO6: 170.9 | MP6: 180.2 | MQ6: 183.2 | MR6: 181.4 | MS6: 189.1 | MT6: 191.9 | MU6: 190.2 | MV6: 192.9 | MW6: 197 | MX6: 194.5 | MY6: 173.9 | MZ6: 177.2 | NA6: 175.2 | NB6: 173.9 | NC6: 177.2 | ND6: 175.2 | NE6: 167.9 | NF6: 172.4 | NG6: 169.6 | NH6: 171 | NI6: 176.7 | NJ6: 173.2
A7: Milk and products | B7: =VLOOKUP(A7, NOTES!C8:D33, 2,0) -> Food | C7: 104.9 | D7: 103.6 | E7: 104.4 | F7: 105.4 | G7: 104 | H7: 104.9 | I7: 105.6 | J7: 104.3 | K7: 105.1 | L7: 106.3 | M7: 104.7 | N7: 105.7 | O7: 107.5 | P7: 105.5 | Q7: 106.8 | R7: 108.3 | S7: 107.3 | T7: 107.9 | U7: 109.3 | V7: 108.3 | W7: 108.9 | X7: 110 | Y7: 108.9 | Z7: 109.6 | AA7: 111 | AB7: 109.6 | AC7: 110.5 | AD7: 111.7 | AE7: 110.4 | AF7: 111.2 | AG7: 112.8 | AH7: 112 | AI7: 112.5 | AJ7: 113.8 | AK7: 112.8 | AL7: 113.4 | AM7: 114.4 | AN7: 113.6 | AO7: 114.1 | AP7: 115 | AQ7: 115.2 | AR7: 115.1 | AS7: 116.1 | AT7: 116.2 | AU7: 116.1 | AV7: 117 | AW7: 117 | AX7: 117 | AY7: 118 | AZ7: 119.1 | BA7: 118.4 | BB7: 119.3 | BC7: 120.4 | BD7: 119.7 | BE7: 120.6 | BF7: 121.6 | BG7: 121 | BH7: 121.9 | BI7: 122.2 | BJ7: 122 | BK7: 122.7 | BL7: 122.7 | BM7: 122.7 | BN7: 123.2 | BO7: 123.1 | BP7: 123.2 | BQ7: 124 | BR7: 124.6 | BS7: 124.2 | BT7: 124.2 | BU7: 124.9 | BV7: 124.5 | BW7: 124.9 | BX7: 125.2 | BY7: 125 | BZ7: 125.8 | CA7: 125.6 | CB7: 125.7 | CC7: 126 | CD7: 125.9 | CE7: 126 | CF7: 126.8 | CG7: 126.3 | CH7: 126.6 | CI7: 127.7 | CJ7: 126.6 | CK7: 127.3 | CL7: 128.7 | CM7: 127.3 | CN7: 128.2 | CO7: 128.7 | CP7: 127.7 | CQ7: 128.3 | CR7: 128.8 | CS7: 128 | CT7: 128.5 | CU7: 129.2 | CV7: 128.3 | CW7: 128.9 | CX7: 129.4 | CY7: 128.5 | CZ7: 129.1 | DA7: 129.5 | DB7: 128.6 | DC7: 129.2 | DD7: 129.8 | DE7: 128.6 | DF7: 129.4 | DG7: 130.3 | DH7: 129.2 | DI7: 129.9 | DJ7: 130.7 | DK7: 129.6 | DL7: 130.3 | DM7: 130.5 | DN7: 129.7 | DO7: 130.2 | DP7: 131.3 | DQ7: 130.2 | DR7: 130.9 | DS7: 132.4 | DT7: 130.4 | DU7: 131.7 | DV7: 133.6 | DW7: 131 | DX7: 132.6 | DY7: 134.5 | DZ7: 131.8 | EA7: 133.5 | EB7: 135.3 | EC7: 132.2 | ED7: 134.1 | EE7: 135.5 | EF7: 132.6 | EG7: 134.4 | EH7: 136 | EI7: 132.7 | EJ7: 134.8 | EK7: 136.2 | EL7: 132.9 | EM7: 135 | EN7: 136.3 | EO7: 133.1 | EP7: 135.1 | EQ7: 136.7 | ER7: 133.1 | ES7: 135.4 | ET7: 137.2 | EU7: 133.5 | EV7: 135.8 | EW7: 137.2 | EX7: 134.9 | EY7: 136.3 | EZ7: 137.7 | FA7: 136.3 | FB7: 137.2 | FC7: 138.2 | FD7: 136.8 | FE7: 137.7 | FF7: 138.6 | FG7: 137.3 | FH7: 138.1 | FI7: 139 | FJ7: 137.7 | FK7: 138.5 | FL7: 139.4 | FM7: 138.3 | FN7: 139 | FO7: 140.2 | FP7: 138.7 | FQ7: 139.6 | FR7: 141.5 | FS7: 139.1 | FT7: 140.6 | FU7: 141.5 | FV7: 139.5 | FW7: 140.8 | FX7: 141.9 | FY7: 139.5 | FZ7: 141 | GA7: 142 | GB7: 139.6 | GC7: 141.1 | GD7: 141.5 | GE7: 139.9 | GF7: 140.9 | GG7: 142 | GH7: 139.9 | GI7: 141.2 | GJ7: 142.4 | GK7: 140.3 | GL7: 141.6 | GM7: 142.9 | GN7: 140.7 | GO7: 142.1 | GP7: 143.2 | GQ7: 140.8 | GR7: 142.3 | GS7: 143.4 | GT7: 141 | GU7: 142.5 | GV7: 143.5 | GW7: 141.2 | GX7: 142.6 | GY7: 143.7 | GZ7: 141.5 | HA7: 142.9 | HB7: 141.9 | HC7: 141.5 | HD7: 141.9 | HE7: 141.9 | HF7: 141.6 | HG7: 141.8 | HH7: 142.4 | HI7: 141.6 | HJ7: 142.1 | HK7: 142.4 | HL7: 141.7 | HM7: 142.1 | HN7: 142.5 | HO7: 141.7 | HP7: 142.2 | HQ7: 142.5 | HR7: 141.9 | HS7: 142.3 | HT7: 142.6 | HU7: 142.4 | HV7: 142.5 | HW7: 143.2 | HX7: 143.4 | HY7: 143.3 | HZ7: 143.9 | IA7: 144.1 | IB7: 144 | IC7: 144.6 | ID7: 144.9 | IE7: 144.7 | IF7: 145.7 | IG7: 144.9 | IH7: 145.4 | II7: 146.5 | IJ7: 145.6 | IK7: 146.2 | IL7: 147.1 | IM7: 145.9 | IN7: 146.7 | IO7: 148.7 | IP7: 147.5 | IQ7: 148.3 | IR7: 150.5 | IS7: 149.3 | IT7: 150.1 | IU7: 150.9 | IV7: 150.7 | IW7: 150.8 | IX7: 151.7 | IY7: 151.1 | IZ7: 151.5 | JA7: 155.6 | JB7: 155.5 | JC7: 155.6 | JD7: NA | JE7: NA | JF7: NA | JG7: 153.3 | JH7: 153.4 | JI7: 153.3 | JJ7: 153.3 | JK7: 153.4 | JL7: 153.3 | JM7: 153.3 | JN7: 153.4 | JO7: 153.3 | JP7: 153.4 | JQ7: 153.9 | JR7: 153.6 | JS7: 153.6 | JT7: 153.7 | JU7: 153.6 | JV7: 153.8 | JW7: 153.9 | JX7: 153.8 | JY7: 154 | JZ7: 154.2 | KA7: 154.1 | KB7: 154 | KC7: 154.4 | KD7: 154.1 | KE7: 154.4 | KF7: 155.1 | KG7: 154.7 | KH7: 154.5 | KI7: 155.6 | KJ7: 154.9 | KK7: 155 | KL7: 156 | KM7: 155.4 | KN7: 155.8 | KO7: 156.5 | KP7: 156.1 | KQ7: 156.1 | KR7: 156.5 | KS7: 156.2 | KT7: 157.1 | KU7: 158.2 | KV7: 157.5 | KW7: 157.5 | KX7: 159.2 | KY7: 158.4 | KZ7: 158 | LA7: 159.1 | LB7: 158.4 | LC7: 158.4 | LD7: 159.2 | LE7: 158.7 | LF7: 159.1 | LG7: 159.6 | LH7: 159.3 | LI7: 159.8 | LJ7: 160 | LK7: 159.9 | LL7: 160.5 | LM7: 160.4 | LN7: 160.5 | LO7: 160.7 | LP7: 160.6 | LQ7: 160.7 | LR7: 162 | LS7: 162.6 | LT7: 162.2 | LU7: 163.8 | LV7: 164.2 | LW7: 163.9 | LX7: 164.6 | LY7: 165.4 | LZ7: 164.9 | MA7: 165.4 | MB7: 166.4 | MC7: 165.8 | MD7: 166.3 | ME7: 167.1 | MF7: 166.6 | MG7: 167.9 | MH7: 168.4 | MI7: 168.1 | MJ7: 169.5 | MK7: 170.1 | ML7: 169.7 | MM7: 170.9 | MN7: 171 | MO7: 170.9 | MP7: 172.3 | MQ7: 172.3 | MR7: 172.3 | MS7: 173.4 | MT7: 173.9 | MU7: 173.6 | MV7: 174.3 | MW7: 175.2 | MX7: 174.6 | MY7: 177 | MZ7: 177.9 | NA7: 177.3 | NB7: 177 | NC7: 177.9 | ND7: 177.3 | NE7: 178.2 | NF7: 178.8 | NG7: 178.4 | NH7: 179.6 | NI7: 179.4 | NJ7: 179.5
A8: Oils and fats | B8: =VLOOKUP(A8, NOTES!C9:D34, 2,0) -> Food | C8: 106.1 | D8: 103.4 | E8: 105.1 | F8: 106.7 | G8: 103.5 | H8: 105.5 | I8: 106.2 | J8: 102.7 | K8: 104.9 | L8: 105.7 | M8: 102.1 | N8: 104.4 | O8: 105.3 | P8: 101.5 | Q8: 103.9 | R8: 105.9 | S8: 101.3 | T8: 104.2 | U8: 106.2 | V8: 101.1 | W8: 104.3 | X8: 106.4 | Y8: 101.1 | Z8: 104.5 | AA8: 107.4 | AB8: 101.7 | AC8: 105.3 | AD8: 107.7 | AE8: 102.3 | AF8: 105.7 | AG8: 108.9 | AH8: 103.2 | AI8: 106.8 | AJ8: 109.5 | AK8: 103.4 | AL8: 107.3 | AM8: 109 | AN8: 102.9 | AO8: 106.8 | AP8: 109 | AQ8: 102.5 | AR8: 106.6 | AS8: 109.3 | AT8: 102.8 | AU8: 106.9 | AV8: 109.7 | AW8: 103.1 | AX8: 107.3 | AY8: 110.1 | AZ8: 103.5 | BA8: 107.7 | BB8: 110.3 | BC8: 103.4 | BD8: 107.8 | BE8: 110.4 | BF8: 103.5 | BG8: 107.9 | BH8: 110.6 | BI8: 103.6 | BJ8: 108 | BK8: 110.4 | BL8: 103.5 | BM8: 107.9 | BN8: 110.5 | BO8: 103.5 | BP8: 107.9 | BQ8: 110.5 | BR8: 103.2 | BS8: 107.8 | BT8: 110.2 | BU8: 103 | BV8: 107.6 | BW8: 111 | BX8: 104.3 | BY8: 108.5 | BZ8: 111.5 | CA8: 104.9 | CB8: 109.1 | CC8: 111.8 | CD8: 104.8 | CE8: 109.2 | CF8: 111.9 | CG8: 104.5 | CH8: 109.2 | CI8: 112.5 | CJ8: 105.2 | CK8: 109.8 | CL8: 114.1 | CM8: 106 | CN8: 111.1 | CO8: 113.5 | CP8: 106.3 | CQ8: 110.9 | CR8: 114 | CS8: 106.8 | CT8: 111.4 | CU8: 114.7 | CV8: 107 | CW8: 111.9 | CX8: 115.8 | CY8: 109 | CZ8: 113.3 | DA8: 117.8 | DB8: 110 | DC8: 114.9 | DD8: 118.3 | DE8: 110 | DF8: 115.3 | DG8: 118.9 | DH8: 109.7 | DI8: 115.5 | DJ8: 118.5 | DK8: 108.4 | DL8: 114.8 | DM8: 118.3 | DN8: 107.9 | DO8: 114.5 | DP8: 118.2 | DQ8: 108.9 | DR8: 114.8 | DS8: 118.2 | DT8: 109.6 | DU8: 115 | DV8: 118.6 | DW8: 110.2 | DX8: 115.5 | DY8: 119.5 | DZ8: 111 | EA8: 116.4 | EB8: 119.9 | EC8: 111.8 | ED8: 116.9 | EE8: 120.2 | EF8: 111.9 | EG8: 117.2 | EH8: 120.8 | EI8: 112.5 | EJ8: 117.8 | EK8: 121.1 | EL8: 112.6 | EM8: 118 | EN8: 121.6 | EO8: 113.5 | EP8: 118.6 | EQ8: 122 | ER8: 114 | ES8: 119.1 | ET8: 122.1 | EU8: 114.3 | EV8: 119.2 | EW8: 121.6 | EX8: 114 | EY8: 118.8 | EZ8: 121.3 | FA8: 113.5 | FB8: 118.4 | FC8: 120.8 | FD8: 113.4 | FE8: 118.1 | FF8: 120.9 | FG8: 113.5 | FH8: 118.2 | FI8: 120.9 | FJ8: 113.4 | FK8: 118.1 | FL8: 120.5 | FM8: 114.1 | FN8: 118.1 | FO8: 120.7 | FP8: 114.5 | FQ8: 118.4 | FR8: 121.4 | FS8: 114.9 | FT8: 119 | FU8: 121.6 | FV8: 115.2 | FW8: 119.2 | FX8: 123.1 | FY8: 115.9 | FZ8: 120.5 | GA8: 123.2 | GB8: 116.4 | GC8: 120.7 | GD8: 122.9 | GE8: 116.2 | GF8: 120.4 | GG8: 123.2 | GH8: 116.5 | GI8: 120.7 | GJ8: 123.5 | GK8: 116.6 | GL8: 121 | GM8: 123.6 | GN8: 116.4 | GO8: 121 | GP8: 124 | GQ8: 116.6 | GR8: 121.3 | GS8: 124.1 | GT8: 116.7 | GU8: 121.4 | GV8: 125 | GW8: 117.4 | GX8: 122.2 | GY8: 124.6 | GZ8: 117.8 | HA8: 122.1 | HB8: 123.5 | HC8: 118 | HD8: 121.1 | HE8: 122.8 | HF8: 118.1 | HG8: 121.1 | HH8: 124.2 | HI8: 118.1 | HJ8: 122 | HK8: 123.9 | HL8: 118.1 | HM8: 121.8 | HN8: 124.1 | HO8: 118.4 | HP8: 122 | HQ8: 124.1 | HR8: 118.4 | HS8: 122 | HT8: 124 | HU8: 118.6 | HV8: 122 | HW8: 124.3 | HX8: 118.6 | HY8: 122.2 | HZ8: 124.4 | IA8: 119.3 | IB8: 122.5 | IC8: 124.7 | ID8: 119.9 | IE8: 122.9 | IF8: 125.1 | IG8: 120.8 | IH8: 123.5 | II8: 125.6 | IJ8: 121.1 | IK8: 123.9 | IL8: 126 | IM8: 121.5 | IN8: 124.3 | IO8: 127.5 | IP8: 122.7 | IQ8: 125.7 | IR8: 132 | IS8: 126.3 | IT8: 129.9 | IU8: 133.7 | IV8: 127.4 | IW8: 131.4 | IX8: 133.3 | IY8: 127.5 | IZ8: 131.2 | JA8: 137.1 | JB8: 131.6 | JC8: 135.1 | JD8: NA | JE8: NA | JF8: NA | JG8: 138.2 | JH8: 132.9 | JI8: 136.3 | JJ8: 138.2 | JK8: 132.9 | JL8: 136.3 | JM8: 139.8 | JN8: 133.4 | JO8: 137.4 | JP8: 140.4 | JQ8: 134.4 | JR8: 138.2 | JS8: 142.6 | JT8: 135.7 | JU8: 140.1 | JV8: 145.4 | JW8: 138 | JX8: 142.7 | JY8: 150 | JZ8: 140.7 | KA8: 146.6 | KB8: 154.8 | KC8: 144.1 | KD8: 150.9 | KE8: 163 | KF8: 151.4 | KG8: 158.7 | KH8: 168.2 | KI8: 156.4 | KJ8: 163.9 | KK8: 175.2 | KL8: 161.4 | KM8: 170.1 | KN8: 184.4 | KO8: 168.8 | KP8: 178.7 | KQ8: 190.4 | KR8: 172.2 | KS8: 183.7 | KT8: 188.7 | KU8: 170.6 | KV8: 182.1 | KW8: 190.9 | KX8: 175 | KY8: 188 | KZ8: 195.5 | LA8: 175 | LB8: 188 | LC8: 198.8 | LD8: 176.6 | LE8: 190.6 | LF8: 198.4 | LG8: 175.8 | LH8: 190.1 | LI8: 195.8 | LJ8: 173.5 | LK8: 187.6 | LL8: 192.6 | LM8: 171 | LN8: 184.7 | LO8: 192.6 | LP8: 171.5 | LQ8: 184.9 | LR8: 203.1 | LS8: 180 | LT8: 194.6 | LU8: 207.4 | LV8: 186 | LW8: 199.5 | LX8: 209.9 | LY8: 189.5 | LZ8: 202.4 | MA8: 208.1 | MB8: 188.6 | MC8: 200.9 | MD8: 202.2 | ME8: 184.8 | MF8: 195.8 | MG8: 198.1 | MH8: 182.5 | MI8: 192.4 | MJ8: 194.1 | MK8: 179.3 | ML8: 188.7 | MM8: 191.6 | MN8: 177.7 | MO8: 186.5 | MP8: 194 | MQ8: 180 | MR8: 188.9 | MS8: 193.9 | MT8: 179.1 | MU8: 188.5 | MV8: 192.6 | MW8: 178 | MX8: 187.2 | MY8: 183.4 | MZ8: 172.2 | NA8: 179.3 | NB8: 183.3 | NC8: 172.2 | ND8: 179.2 | NE8: 178.5 | NF8: 168.7 | NG8: 174.9 | NH8: 173.3 | NI8: 164.4 | NJ8: 170
A9: Fruits | B9: =VLOOKUP(A9, NOTES!C10:D35, 2,0) -> Food | C9: 103.9 | D9: 102.3 | E9: 103.2 | F9: 104 | G9: 103.1 | H9: 103.6 | I9: 105.7 | J9: 104.9 | K9: 105.3 | L9: 108.3 | M9: 109.5 | N9: 108.9 | O9: 108.1 | P9: 110.6 | Q9: 109.3 | R9: 109.2 | S9: 112.4 | T9: 110.7 | U9: 110.3 | V9: 113.2 | W9: 111.7 | X9: 110.8 | Y9: 108.7 | Z9: 109.8 | AA9: 110.9 | AB9: 103.2 | AC9: 107.3 | AD9: 113.2 | AE9: 106.2 | AF9: 109.9 | AG9: 116.6 | AH9: 110 | AI9: 113.5 | AJ9: 115.5 | AK9: 110.7 | AL9: 113.3 | AM9: 115.5 | AN9: 112.1 | AO9: 113.9 | AP9: 116.6 | AQ9: 114.1 | AR9: 115.4 | AS9: 119.6 | AT9: 117.7 | AU9: 118.7 | AV9: 125.5 | AW9: 126.7 | AX9: 126.1 | AY9: 126.3 | AZ9: 129.2 | BA9: 127.7 | BB9: 125.8 | BC9: 131.2 | BD9: 128.3 | BE9: 129.1 | BF9: 133.7 | BG9: 131.2 | BH9: 129.7 | BI9: 132.7 | BJ9: 131.1 | BK9: 129.8 | BL9: 124.5 | BM9: 127.3 | BN9: 128.9 | BO9: 123.5 | BP9: 126.4 | BQ9: 128.8 | BR9: 122.2 | BS9: 125.7 | BT9: 128.6 | BU9: 122.3 | BV9: 125.7 | BW9: 130.4 | BX9: 121.3 | BY9: 126.2 | BZ9: 129.4 | CA9: 121.6 | CB9: 125.8 | CC9: 130.9 | CD9: 123.8 | CE9: 127.6 | CF9: 134.2 | CG9: 130.6 | CH9: 132.5 | CI9: 134.1 | CJ9: 130.8 | CK9: 132.6 | CL9: 133.2 | CM9: 132.3 | CN9: 132.8 | CO9: 133.3 | CP9: 132.8 | CQ9: 133.1 | CR9: 134.2 | CS9: 130.1 | CT9: 132.3 | CU9: 132.3 | CV9: 124 | CW9: 128.4 | CX9: 133.2 | CY9: 124.1 | CZ9: 129 | DA9: 132.1 | DB9: 123.7 | DC9: 128.2 | DD9: 131.6 | DE9: 120.8 | DF9: 126.6 | DG9: 131.6 | DH9: 119 | DI9: 125.7 | DJ9: 130.4 | DK9: 118.6 | DL9: 124.9 | DM9: 131.7 | DN9: 119.9 | DO9: 126.2 | DP9: 138.1 | DQ9: 131.1 | DR9: 134.8 | DS9: 138.1 | DT9: 133.5 | DU9: 136 | DV9: 137.4 | DW9: 135.5 | DX9: 136.5 | DY9: 138.5 | DZ9: 137 | EA9: 137.8 | EB9: 140.2 | EC9: 135.8 | ED9: 138.1 | EE9: 139.2 | EF9: 132.5 | EG9: 136.1 | EH9: 138.4 | EI9: 130.4 | EJ9: 134.7 | EK9: 136.9 | EL9: 130.8 | EM9: 134.1 | EN9: 135.6 | EO9: 129.3 | EP9: 132.7 | EQ9: 136 | ER9: 129.6 | ES9: 133 | ET9: 138.7 | EU9: 131.4 | EV9: 135.3 | EW9: 139.7 | EX9: 136.8 | EY9: 138.3 | EZ9: 141.8 | FA9: 137.7 | FB9: 139.9 | FC9: 140.2 | FD9: 135.2 | FE9: 137.9 | FF9: 140.9 | FG9: 137.2 | FH9: 139.2 | FI9: 143.9 | FJ9: 139.4 | FK9: 141.8 | FL9: 148 | FM9: 142.7 | FN9: 145.5 | FO9: 147.8 | FP9: 137.5 | FQ9: 143 | FR9: 146.7 | FS9: 135.6 | FT9: 141.5 | FU9: 147.3 | FV9: 136.4 | FW9: 142.2 | FX9: 147.2 | FY9: 135 | FZ9: 141.5 | GA9: 147.9 | GB9: 133.8 | GC9: 141.3 | GD9: 149.4 | GE9: 135.5 | GF9: 142.9 | GG9: 152.9 | GH9: 138.5 | GI9: 146.2 | GJ9: 156.4 | GK9: 150.1 | GL9: 153.5 | GM9: 157.5 | GN9: 151.3 | GO9: 154.6 | GP9: 154.1 | GQ9: 152.2 | GR9: 153.2 | GS9: 153.3 | GT9: 149.7 | GU9: 151.6 | GV9: 154.4 | GW9: 146.3 | GX9: 150.6 | GY9: 150.1 | GZ9: 140 | HA9: 145.4 | HB9: 144.5 | HC9: 139.5 | HD9: 142.5 | HE9: 143.9 | HF9: 141.5 | HG9: 142.8 | HH9: 140.2 | HI9: 138.5 | HJ9: 139.4 | HK9: 135.5 | HL9: 135.2 | HM9: 135.4 | HN9: 135.8 | HO9: 137 | HP9: 136.4 | HQ9: 136.1 | HR9: 139.4 | HS9: 137.6 | HT9: 143.7 | HU9: 149.7 | HV9: 146.5 | HW9: 143.3 | HX9: 150.9 | HY9: 146.8 | HZ9: 146.4 | IA9: 154.7 | IB9: 150.3 | IC9: 145.5 | ID9: 153.9 | IE9: 149.4 | IF9: 143.8 | IG9: 149.8 | IH9: 146.6 | II9: 145.7 | IJ9: 150.6 | IK9: 148 | IL9: 146.2 | IM9: 148.8 | IN9: 147.4 | IO9: 144.3 | IP9: 147.2 | IQ9: 145.7 | IR9: 142.2 | IS9: 144.4 | IT9: 143.2 | IU9: 140.7 | IV9: 143.1 | IW9: 141.8 | IX9: 141.8 | IY9: 143.3 | IZ9: 142.5 | JA9: 147.3 | JB9: 152.9 | JC9: 149.9 | JD9: NA | JE9: NA | JF9: NA | JG9: 143.2 | JH9: 151.8 | JI9: 147.2 | JJ9: 143.2 | JK9: 151.8 | JL9: 147.2 | JM9: 146.9 | JN9: 154.5 | JO9: 150.4 | JP9: 147 | JQ9: 155.4 | JR9: 150.9 | JS9: 147.2 | JT9: 155.7 | JU9: 151.2 | JV9: 146.5 | JW9: 150.5 | JX9: 148.4 | JY9: 145.9 | JZ9: 149.7 | KA9: 147.7 | KB9: 147 | KC9: 152.6 | KD9: 149.6 | KE9: 147.8 | KF9: 154 | KG9: 150.7 | KH9: 150.5 | KI9: 157.3 | KJ9: 153.7 | KK9: 160.6 | KL9: 168.8 | KM9: 164.4 | KN9: 162.3 | KO9: 172.5 | KP9: 167.1 | KQ9: 158.6 | KR9: 171.5 | KS9: 164.6 | KT9: 157.7 | KU9: 170.9 | KV9: 163.9 | KW9: 155.7 | KX9: 161.3 | KY9: 156.8 | KZ9: 152.7 | LA9: 161.2 | LB9: 156.7 | LC9: 152.6 | LD9: 159.3 | LE9: 155.7 | LF9: 153.2 | LG9: 160.3 | LH9: 156.5 | LI9: 152 | LJ9: 158.3 | LK9: 154.9 | LL9: 151.2 | LM9: 156.5 | LN9: 153.7 | LO9: 151.4 | LP9: 156.4 | LQ9: 153.7 | LR9: 155.9 | LS9: 159.6 | LT9: 157.6 | LU9: 169.7 | LV9: 175.9 | LW9: 172.6 | LX9: 168 | LY9: 174.5 | LZ9: 171 | MA9: 165.8 | MB9: 174.1 | MC9: 169.7 | MD9: 169.6 | ME9: 179.5 | MF9: 174.2 | MG9: 169.2 | MH9: 177.1 | MI9: 172.9 | MJ9: 164.1 | MK9: 167.5 | ML9: 165.7 | MM9: 162.2 | MN9: 165.7 | MO9: 163.8 | MP9: 159.1 | MQ9: 162.6 | MR9: 160.7 | MS9: 156.7 | MT9: 159.5 | MU9: 158 | MV9: 156.3 | MW9: 160.5 | MX9: 158.3 | MY9: 167.2 | MZ9: 172.1 | NA9: 169.5 | NB9: 167.2 | NC9: 172.1 | ND9: 169.5 | NE9: 173.7 | NF9: 179.2 | NG9: 176.3 | NH9: 169 | NI9: 175.8 | NJ9: 172.2
